Workbook

Sheet Sheet1
D2: Ahlgren, Benjamin A | E2: Ben@integrityspecialists.com
D3: Alfonso, Marco | E3: Malfonso@integrityspecialists.com | F3: Advanced Technician
D4: Arceneaux, Austin | E4: Aarceneaux@integrityspecialists.com | F4: Advanced Technician
D5: Barlow, Alec | E5: Abarlow@integrityspecialists.com | F5: Project Manager
D6: Barta, Toby | E6: Tbarta@integrityspecialists.com | F6: Advanced Technician
D7: Becenti, Jordan | E7: Jbecenti@integrityspecialists.com | F7: Advanced Technician
D8: Canales, Camiren | E8: Ccanales@integrityspecialists.com | F8: Senior Technician
D9: Cottingham, Christian | E9: Ccottingham@integrityspecialists.com | F9: Advanced Technician
D10: Cuéllar, René | E10: Rcuellar@integrityspecialists.com | F10: Senior Technician
D11: Delgado, Luis | E11: Ldelgado@integrityspecialists.com | F11: Senior Technician
D12: Diaz, Miguel | E12: Mdiaz@integrityspecialists.com | F12: Senior Technician
D13: Drain, Jared | E13: Jdrain@integrityspecialists.com | F13: Senior Technician
D14: Dunn, David | E14: Ddunn@integrityspecialists.com | F14: Senior Technician
... D22: Harmon, Wade | E22: Wharmon@integrityspecialists.com | F22: Advanced Technician
D23: Harwood, Matthew T | E23: Matt@integrityspecialists.com
D24: Holbrook, Dominic | E24: Dholbrook@integrityspecialists.com | F24: Advanced Technician
D25: Holland, Tristan | E25: Tholland@integrityspecialists.com | F25: Advanced Technician
D26: Jiron, Jaylon | E26: Jjiron@integrityspecialists.com | F26: Senior Technician
D27: Johnson, Karson | E27: Kjohnson@integrityspecialists.com | F27: Advanced Technician
D28: Jones, Matthew E | E28: Mjones@integrityspecialists.com | F28: Project Manager
D29: Lindenfelser, Mike | E29: Mlindenfelser@integrityspecialists.com | F29: Advanced Technician
D30: Loveland, Justin T (Tyler) | E30: Tyler@integrityspecialists.com | F30: Advanced Technician
D31: Martinez, Xavier | E31: Xmartinez@integrityspecialists.com | F31: Advanced Technician
D32: Mattila, Ted | E32: Tmattila@integrityspecialists.com | F32: Advanced Technician
D33: Metcalf, Levi | E33: Lmetcalf@integrityspecialists.com | F33: Project Manager
D34: Miller, Matthew L | E34: Mmiller@integrityspecialists.com | F34: Project Manager
D35: Name | E35: E-Mail | F35: Job Title
... D37: Reid, Ross | E37: Rreid@integrityspecialists.com | F37: Advanced Technician
D38: Ripper, Thomas R (Tommy) | E38: Tripper@integrityspecialists.com
D39: Roberston, Stormy | E39: Srobertson@integrityspecialists.com | F39: Advanced Technician
D40: Scarborough, Zachary | E40: Zscarborough@integrityspecialists.com | F40: Advanced Technician
D41: Schewe, Larry J | E41: Larry@integrityspecialists.com | F41: ASNT Level III
D42: Sierra, Jonatan | E42: Jsierra@integrityspecialists.com | F42: Senior Technician
D43: Silva, Brandon | E43: Bsilva@integrityspecialists.com | F43: Advanced Technician
D44: Sims, Justin K | E44: Jsims@integrityspecialists.com | F44: Advanced Technician
D45: Slusar, Travis | E45: Tslusar@integrityspecialists.com | F45: Advanced Technician
D46: Smith, Jim | E46: Jim@integrityspecialists.com | F46: Project Manager
D47: Smith, Mason D | E47: Mason@integrityspecialists.com | F47: Project Manager
D48: Vancour, Sean | E48: Svancour@integrityspecialists.com | F48: Senior Technician
D49: Vanderstelt, Joseph | E49: Joe@integrityspecialists.com | F49: Advanced Technician
...

Sheet Jan
F1: Integrity Specialists, LLC 1151 Business Blvd Annandale, MN 55302 PH 503-437-3273
AA2: {=IFERROR(_xlfn.UNIQUE(_xlfn._xlws.FILTER(J7:J37,J7:J37<>"")),"")} | AB2: =COUNTA(AA:AA) -> 1
A3: Time in Method Summary
A4: Name: | B4: Your Name | C4: January | F4: 2024
E5: HOURS | J5: Supervising Technician
A6: Date | B6: Location | C6: MT | D6: PT | E6: ET | F6: UT | G6: VT | H6: LM | I6: PAUT
A7: {=IFERROR( _xlfn.LET( _xlpm.yr,$F$4, _xlpm.mn,IF(ISNUMBER($C$4),$C$4,MONTH(1&$C$4)), _xlpm.first,DATE(_xlpm.yr,_xlpm.mn,1), _xlpm.daysInMonth,DAY(EOMONTH(_xlpm.first,0)), TEXT(_xlpm.first+_xlfn.SEQUENCE(_xlpm.daysInMonth)-1,"dddd, mmmm d, yyyy") ), "")} -> Monday, January 1, 2024
A8: Tuesday, January 2, 2024
A9: Wednesday, January 3, 2024
A10: Thursday, January 4, 2024
A11: Friday, January 5, 2024
A12: Saturday, January 6, 2024
A13: Sunday, January 7, 2024
A14: Monday, January 8, 2024
A15: Tuesday, January 9, 2024
A16: Wednesday, January 10, 2024
A17: Thursday, January 11, 2024
A18: Friday, January 12, 2024
A19: Saturday, January 13, 2024
... A37: Wednesday, January 31, 2024
B40: =C4&" "&F4&" HOURS" -> January 2024 HOURS | C40: =SUM(C7:C39) -> 0 | D40: =SUM(D7:D39) -> 0 | E40: =SUM(E7:E39) -> 0 | F40: =SUM(F7:F39) -> 0 | G40: =SUM(G7:G39) -> 0 | H40: =SUM(H7:H39) -> 0 | I40: =SUM(I7:I39) -> 0
A44: =IFERROR(IF(A45="","","X"),"") | F44: =IFERROR(IF(F45="","","X"),"") | G44: =IFERROR(IF(G45="","","X"),"") | H44: =IFERROR(IF(H45="","","X"),"") | I44: =IFERROR(IF(I45="","","X"),"")
A45: =IFERROR(IF(AB2>0,AA2,""),"") | F45: =IFERROR(IF(AB$2>1,AA3,""),"")
A46: =IFERROR(VLOOKUP(A45,Sheet1!$D$2:$F$52,3,TRUE),"") | F46: =IFERROR(VLOOKUP(F45,Sheet1!$D$2:$F$52,3,TRUE),"") | G46: =IFERROR(VLOOKUP(G45,Sheet1!$D$2:$F$52,3,TRUE),"") | H46: =IFERROR(VLOOKUP(H45,Sheet1!$D$2:$F$52,3,TRUE),"") | I46: =IFERROR(VLOOKUP(I45,Sheet1!$D$2:$F$52,3,TRUE),"")
A47: =IFERROR(VLOOKUP(A45,Sheet1!$D$2:$F$52,2,TRUE),"") | F47: =IFERROR(VLOOKUP(F45,Sheet1!$D$2:$F$52,2,TRUE),"") | G47: =IFERROR(VLOOKUP(G45,Sheet1!$D$2:$F$52,2,TRUE),"") | H47: =IFERROR(VLOOKUP(H45,Sheet1!$D$2:$F$52,2,TRUE),"") | I47: =IFERROR(VLOOKUP(I45,Sheet1!$D$2:$F$52,2,TRUE),"")
A50: =IFERROR(IF(A51="","","X"),"") | F50: =IFERROR(IF(F51="","","X"),"")
A51: =IFERROR(IF(AB2>2,AA4,""),"") | F51: =IFERROR(IF(AB2>3,AA5,""),"")
A52: =IFERROR(VLOOKUP(A51,Sheet1!$D$2:$F$52,3,TRUE),"") | F52: =IFERROR(VLOOKUP(F51,Sheet1!$D$2:$F$52,3,TRUE),"")
A53: =IFERROR(VLOOKUP(A51,Sheet1!$D$2:$F$52,2,TRUE),"") | F53: =IFERROR(VLOOKUP(F51,Sheet1!$D$2:$F$52,2,TRUE),"")
A56: =IFERROR(IF(A57="","","X"),"") | F56: =IFERROR(IF(F57="","","X"),"")
A57: =IFERROR(IF(AB2>4,AA6,""),"") | F57: =IFERROR(IF(AB2>5,AA7,""),"")
A58: =IFERROR(VLOOKUP(A57,Sheet1!$D$2:$F$52,3,TRUE),"") | F58: =IFERROR(VLOOKUP(F57,Sheet1!$D$2:$F$52,3,TRUE),"")
A59: =IFERROR(VLOOKUP(A57,Sheet1!$D$2:$F$52,2,TRUE),"") | F59: =IFERROR(VLOOKUP(F57,Sheet1!$D$2:$F$52,2,TRUE),"")

Sheet Feb
F1: Integrity Specialists, LLC 1151 Business Blvd Annandale, MN 55302 PH 503-437-3273
AA2: {=IFERROR(_xlfn.UNIQUE(_xlfn._xlws.FILTER(J7:J35,J7:J35<>"")),"")} | AB2: =COUNTA(AA:AA) -> 1
A3: Time in Method Summary
A4: Name: | B4: =IF(Jan!B4="","",Jan!B4) -> Your Name | C4: February | F4: =Jan!F4 -> 2024
E5: HOURS | J5: Supervising Technician
A6: Date | B6: Location | C6: MT | D6: PT | E6: ET | F6: UT | G6: VT | H6: LM | I6: PAUT
A7: {=IFERROR( _xlfn.LET( _xlpm.yr,$F$4, _xlpm.mn,IF(ISNUMBER($C$4),$C$4,MONTH(1&$C$4)), _xlpm.first,DATE(_xlpm.yr,_xlpm.mn,1), _xlpm.daysInMonth,DAY(EOMONTH(_xlpm.first,0)), TEXT(_xlpm.first+_xlfn.SEQUENCE(_xlpm.daysInMonth)-1,"dddd, mmmm d, yyyy") ), "")} -> Thursday, February 1, 2024
A8: Friday, February 2, 2024
A9: Saturday, February 3, 2024
A10: Sunday, February 4, 2024
A11: Monday, February 5, 2024
A12: Tuesday, February 6, 2024
A13: Wednesday, February 7, 2024
A14: Thursday, February 8, 2024
A15: Friday, February 9, 2024
A16: Saturday, February 10, 2024
A17: Sunday, February 11, 2024
A18: Monday, February 12, 2024
A19: Tuesday, February 13, 2024
... A35: Thursday, February 29, 2024
B38: =C4&" "&F4&" HOURS" -> February 2024 HOURS | C38: =SUM(C7:C37) -> 0 | D38: =SUM(D7:D37) -> 0 | E38: =SUM(E7:E37) -> 0 | F38: =SUM(F7:F37) -> 0 | G38: =SUM(G7:G37) -> 0 | H38: =SUM(H7:H37) -> 0 | I38: =SUM(I7:I37) -> 0
A42: =IFERROR(IF(A43="","","X"),"") | F42: =IFERROR(IF(F43="","","X"),"") | G42: =IFERROR(IF(G43="","","X"),"") | H42: =IFERROR(IF(H43="","","X"),"") | I42: =IFERROR(IF(I43="","","X"),"")
A43: =IFERROR(IF(AB2>0,AA2,""),"") | F43: =IFERROR(IF(AB$2>1,AA3,""),"")
A44: =IFERROR(VLOOKUP(A43,Sheet1!$D$2:$F$52,3,TRUE),"") | F44: =IFERROR(VLOOKUP(F43,Sheet1!$D$2:$F$52,3,TRUE),"") | G44: =IFERROR(VLOOKUP(G43,Sheet1!$D$2:$F$52,3,TRUE),"") | H44: =IFERROR(VLOOKUP(H43,Sheet1!$D$2:$F$52,3,TRUE),"") | I44: =IFERROR(VLOOKUP(I43,Sheet1!$D$2:$F$52,3,TRUE),"")
A45: =IFERROR(VLOOKUP(A43,Sheet1!$D$2:$F$52,2,TRUE),"") | F45: =IFERROR(VLOOKUP(F43,Sheet1!$D$2:$F$52,2,TRUE),"") | G45: =IFERROR(VLOOKUP(G43,Sheet1!$D$2:$F$52,2,TRUE),"") | H45: =IFERROR(VLOOKUP(H43,Sheet1!$D$2:$F$52,2,TRUE),"") | I45: =IFERROR(VLOOKUP(I43,Sheet1!$D$2:$F$52,2,TRUE),"")
A48: =IFERROR(IF(A49="","","X"),"") | F48: =IFERROR(IF(F49="","","X"),"")
A49: =IFERROR(IF(AB2>2,AA4,""),"") | F49: =IFERROR(IF(AB2>3,AA5,""),"")
A50: =IFERROR(VLOOKUP(A49,Sheet1!$D$2:$F$52,3,TRUE),"") | F50: =IFERROR(VLOOKUP(F49,Sheet1!$D$2:$F$52,3,TRUE),"")
A51: =IFERROR(VLOOKUP(A49,Sheet1!$D$2:$F$52,2,TRUE),"") | F51: =IFERROR(VLOOKUP(F49,Sheet1!$D$2:$F$52,2,TRUE),"")
A54: =IFERROR(IF(A55="","","X"),"") | F54: =IFERROR(IF(F55="","","X"),"")
A55: =IFERROR(IF(AB2>4,AA6,""),"") | F55: =IFERROR(IF(AB2>5,AA7,""),"")
A56: =IFERROR(VLOOKUP(A55,Sheet1!$D$2:$F$52,3,TRUE),"") | F56: =IFERROR(VLOOKUP(F55,Sheet1!$D$2:$F$52,3,TRUE),"")
A57: =IFERROR(VLOOKUP(A55,Sheet1!$D$2:$F$52,2,TRUE),"") | F57: =IFERROR(VLOOKUP(F55,Sheet1!$D$2:$F$52,2,TRUE),"")

Sheet Mar
F1: Integrity Specialists, LLC 1151 Business Blvd Annandale, MN 55302 PH 503-437-3273
AA2: {=IFERROR(_xlfn.UNIQUE(_xlfn._xlws.FILTER(J7:J37,J7:J37<>"")),"")} | AB2: =COUNTA(AA:AA) -> 1
A3: Time in Method Summary
A4: Name: | B4: =IF(Jan!B4="","",Jan!B4) -> Your Name | C4: March | F4: =Jan!F4 -> 2024
E5: HOURS | J5: Supervising Technician
A6: Date | B6: Location | C6: MT | D6: PT | E6: ET | F6: UT | G6: VT | H6: LM | I6: PAUT
A7: {=IFERROR( _xlfn.LET( _xlpm.yr,$F$4, _xlpm.mn,IF(ISNUMBER($C$4),$C$4,MONTH(1&$C$4)), _xlpm.first,DATE(_xlpm.yr,_xlpm.mn,1), _xlpm.daysInMonth,DAY(EOMONTH(_xlpm.first,0)), TEXT(_xlpm.first+_xlfn.SEQUENCE(_xlpm.daysInMonth)-1,"dddd, mmmm d, yyyy") ), "")} -> Friday, March 1, 2024
A8: Saturday, March 2, 2024
A9: Sunday, March 3, 2024
A10: Monday, March 4, 2024
A11: Tuesday, March 5, 2024
A12: Wednesday, March 6, 2024
A13: Thursday, March 7, 2024
A14: Friday, March 8, 2024
A15: Saturday, March 9, 2024
A16: Sunday, March 10, 2024
A17: Monday, March 11, 2024
A18: Tuesday, March 12, 2024
A19: Wednesday, March 13, 2024
... A37: Sunday, March 31, 2024
B40: =C4&" "&F4&" HOURS" -> March 2024 HOURS | C40: =SUM(C7:C39) -> 0 | D40: =SUM(D7:D39) -> 0 | E40: =SUM(E7:E39) -> 0 | F40: =SUM(F7:F39) -> 0 | G40: =SUM(G7:G39) -> 0 | H40: =SUM(H7:H39) -> 0 | I40: =SUM(I7:I39) -> 0
A44: =IFERROR(IF(A45="","","X"),"") | F44: =IFERROR(IF(F45="","","X"),"") | G44: =IFERROR(IF(G45="","","X"),"") | H44: =IFERROR(IF(H45="","","X"),"") | I44: =IFERROR(IF(I45="","","X"),"")
A45: =IFERROR(IF(AB2>0,AA2,""),"") | F45: =IFERROR(IF(AB$2>1,AA3,""),"")
A46: =IFERROR(VLOOKUP(A45,Sheet1!$D$2:$F$52,3,TRUE),"") | F46: =IFERROR(VLOOKUP(F45,Sheet1!$D$2:$F$52,3,TRUE),"") | G46: =IFERROR(VLOOKUP(G45,Sheet1!$D$2:$F$52,3,TRUE),"") | H46: =IFERROR(VLOOKUP(H45,Sheet1!$D$2:$F$52,3,TRUE),"") | I46: =IFERROR(VLOOKUP(I45,Sheet1!$D$2:$F$52,3,TRUE),"")
A47: =IFERROR(VLOOKUP(A45,Sheet1!$D$2:$F$52,2,TRUE),"") | F47: =IFERROR(VLOOKUP(F45,Sheet1!$D$2:$F$52,2,TRUE),"") | G47: =IFERROR(VLOOKUP(G45,Sheet1!$D$2:$F$52,2,TRUE),"") | H47: =IFERROR(VLOOKUP(H45,Sheet1!$D$2:$F$52,2,TRUE),"") | I47: =IFERROR(VLOOKUP(I45,Sheet1!$D$2:$F$52,2,TRUE),"")
A50: =IFERROR(IF(A51="","","X"),"") | F50: =IFERROR(IF(F51="","","X"),"")
A51: =IFERROR(IF(AB2>2,AA4,""),"") | F51: =IFERROR(IF(AB2>3,AA5,""),"")
A52: =IFERROR(VLOOKUP(A51,Sheet1!$D$2:$F$52,3,TRUE),"") | F52: =IFERROR(VLOOKUP(F51,Sheet1!$D$2:$F$52,3,TRUE),"")
A53: =IFERROR(VLOOKUP(A51,Sheet1!$D$2:$F$52,2,TRUE),"") | F53: =IFERROR(VLOOKUP(F51,Sheet1!$D$2:$F$52,2,TRUE),"")
A56: =IFERROR(IF(A57="","","X"),"") | F56: =IFERROR(IF(F57="","","X"),"")
A57: =IFERROR(IF(AB2>4,AA6,""),"") | F57: =IFERROR(IF(AB2>5,AA7,""),"")
A58: =IFERROR(VLOOKUP(A57,Sheet1!$D$2:$F$52,3,TRUE),"") | F58: =IFERROR(VLOOKUP(F57,Sheet1!$D$2:$F$52,3,TRUE),"")
A59: =IFERROR(VLOOKUP(A57,Sheet1!$D$2:$F$52,2,TRUE),"") | F59: =IFERROR(VLOOKUP(F57,Sheet1!$D$2:$F$52,2,TRUE),"")

Sheet Apr
F1: Integrity Specialists, LLC 1151 Business Blvd Annandale, MN 55302 PH 503-437-3273
AA2: {=IFERROR(_xlfn.UNIQUE(_xlfn._xlws.FILTER(J7:J36,J7:J36<>"")),"")} | AB2: =COUNTA(AA:AA) -> 1
A3: Time in Method Summary
A4: Name: | B4: =IF(Jan!B4="","",Jan!B4) -> Your Name | C4: April | F4: =Jan!F4 -> 2024
E5: HOURS | J5: Supervising Technician
A6: Date | B6: Location | C6: MT | D6: PT | E6: ET | F6: UT | G6: VT | H6: LM | I6: PAUT
A7: {=IFERROR( _xlfn.LET( _xlpm.yr,$F$4, _xlpm.mn,IF(ISNUMBER($C$4),$C$4,MONTH(1&$C$4)), _xlpm.first,DATE(_xlpm.yr,_xlpm.mn,1), _xlpm.daysInMonth,DAY(EOMONTH(_xlpm.first,0)), TEXT(_xlpm.first+_xlfn.SEQUENCE(_xlpm.daysInMonth)-1,"dddd, mmmm d, yyyy") ), "")} -> Monday, April 1, 2024
A8: Tuesday, April 2, 2024
A9: Wednesday, April 3, 2024
A10: Thursday, April 4, 2024
A11: Friday, April 5, 2024
A12: Saturday, April 6, 2024
A13: Sunday, April 7, 2024
A14: Monday, April 8, 2024
A15: Tuesday, April 9, 2024
A16: Wednesday, April 10, 2024
A17: Thursday, April 11, 2024
A18: Friday, April 12, 2024
A19: Saturday, April 13, 2024
... A36: Tuesday, April 30, 2024
B39: =C4&" "&F4&" HOURS" -> April 2024 HOURS | C39: =SUM(C7:C38) -> 0 | D39: =SUM(D7:D38) -> 0 | E39: =SUM(E7:E38) -> 0 | F39: =SUM(F7:F38) -> 0 | G39: =SUM(G7:G38) -> 0 | H39: =SUM(H7:H38) -> 0 | I39: =SUM(I7:I38) -> 0
A43: =IFERROR(IF(A44="","","X"),"") | F43: =IFERROR(IF(F44="","","X"),"") | G43: =IFERROR(IF(G44="","","X"),"") | H43: =IFERROR(IF(H44="","","X"),"") | I43: =IFERROR(IF(I44="","","X"),"")
A44: =IFERROR(IF(AB2>0,AA2,""),"") | F44: =IFERROR(IF(AB$2>1,AA3,""),"")
A45: =IFERROR(VLOOKUP(A44,Sheet1!$D$2:$F$52,3,TRUE),"") | F45: =IFERROR(VLOOKUP(F44,Sheet1!$D$2:$F$52,3,TRUE),"") | G45: =IFERROR(VLOOKUP(G44,Sheet1!$D$2:$F$52,3,TRUE),"") | H45: =IFERROR(VLOOKUP(H44,Sheet1!$D$2:$F$52,3,TRUE),"") | I45: =IFERROR(VLOOKUP(I44,Sheet1!$D$2:$F$52,3,TRUE),"")
A46: =IFERROR(VLOOKUP(A44,Sheet1!$D$2:$F$52,2,TRUE),"") | F46: =IFERROR(VLOOKUP(F44,Sheet1!$D$2:$F$52,2,TRUE),"") | G46: =IFERROR(VLOOKUP(G44,Sheet1!$D$2:$F$52,2,TRUE),"") | H46: =IFERROR(VLOOKUP(H44,Sheet1!$D$2:$F$52,2,TRUE),"") | I46: =IFERROR(VLOOKUP(I44,Sheet1!$D$2:$F$52,2,TRUE),"")
A49: =IFERROR(IF(A50="","","X"),"") | F49: =IFERROR(IF(F50="","","X"),"")
A50: =IFERROR(IF(AB2>2,AA4,""),"") | F50: =IFERROR(IF(AB2>3,AA5,""),"")
A51: =IFERROR(VLOOKUP(A50,Sheet1!$D$2:$F$52,3,TRUE),"") | F51: =IFERROR(VLOOKUP(F50,Sheet1!$D$2:$F$52,3,TRUE),"")
A52: =IFERROR(VLOOKUP(A50,Sheet1!$D$2:$F$52,2,TRUE),"") | F52: =IFERROR(VLOOKUP(F50,Sheet1!$D$2:$F$52,2,TRUE),"")
A55: =IFERROR(IF(A56="","","X"),"") | F55: =IFERROR(IF(F56="","","X"),"")
A56: =IFERROR(IF(AB2>4,AA6,""),"") | F56: =IFERROR(IF(AB2>5,AA7,""),"")
A57: =IFERROR(VLOOKUP(A56,Sheet1!$D$2:$F$52,3,TRUE),"") | F57: =IFERROR(VLOOKUP(F56,Sheet1!$D$2:$F$52,3,TRUE),"")
A58: =IFERROR(VLOOKUP(A56,Sheet1!$D$2:$F$52,2,TRUE),"") | F58: =IFERROR(VLOOKUP(F56,Sheet1!$D$2:$F$52,2,TRUE),"")

Sheet May
F1: Integrity Specialists, LLC 1151 Business Blvd Annandale, MN 55302 PH 503-437-3273
AA2: {=IFERROR(_xlfn.UNIQUE(_xlfn._xlws.FILTER(J7:J37,J7:J37<>"")),"")} | AB2: =COUNTA(AA:AA) -> 1
A3: Time in Method Summary
A4: Name: | B4: =IF(Jan!B4="","",Jan!B4) -> Your Name | C4: May | F4: =Jan!F4 -> 2024
E5: HOURS | J5: Supervising Technician
A6: Date | B6: Location | C6: MT | D6: PT | E6: ET | F6: UT | G6: VT | H6: LM | I6: PAUT
A7: {=IFERROR( _xlfn.LET( _xlpm.yr,$F$4, _xlpm.mn,IF(ISNUMBER($C$4),$C$4,MONTH(1&$C$4)), _xlpm.first,DATE(_xlpm.yr,_xlpm.mn,1), _xlpm.daysInMonth,DAY(EOMONTH(_xlpm.first,0)), TEXT(_xlpm.first+_xlfn.SEQUENCE(_xlpm.daysInMonth)-1,"dddd, mmmm d, yyyy") ), "")} -> Wednesday, May 1, 2024
A8: Thursday, May 2, 2024
A9: Friday, May 3, 2024
A10: Saturday, May 4, 2024
A11: Sunday, May 5, 2024
A12: Monday, May 6, 2024
A13: Tuesday, May 7, 2024
A14: Wednesday, May 8, 2024
A15: Thursday, May 9, 2024
A16: Friday, May 10, 2024
A17: Saturday, May 11, 2024
A18: Sunday, May 12, 2024
A19: Monday, May 13, 2024
... A37: Friday, May 31, 2024
B40: =C4&" "&F4&" HOURS" -> May 2024 HOURS | C40: =SUM(C7:C39) -> 0 | D40: =SUM(D7:D39) -> 0 | E40: =SUM(E7:E39) -> 0 | F40: =SUM(F7:F39) -> 0 | G40: =SUM(G7:G39) -> 0 | H40: =SUM(H7:H39) -> 0 | I40: =SUM(I7:I39) -> 0
A44: =IFERROR(IF(A45="","","X"),"") | F44: =IFERROR(IF(F45="","","X"),"") | G44: =IFERROR(IF(G45="","","X"),"") | H44: =IFERROR(IF(H45="","","X"),"") | I44: =IFERROR(IF(I45="","","X"),"")
A45: =IFERROR(IF(AB2>0,AA2,""),"") | F45: =IFERROR(IF(AB$2>1,AA3,""),"")
A46: =IFERROR(VLOOKUP(A45,Sheet1!$D$2:$F$52,3,TRUE),"") | F46: =IFERROR(VLOOKUP(F45,Sheet1!$D$2:$F$52,3,TRUE),"") | G46: =IFERROR(VLOOKUP(G45,Sheet1!$D$2:$F$52,3,TRUE),"") | H46: =IFERROR(VLOOKUP(H45,Sheet1!$D$2:$F$52,3,TRUE),"") | I46: =IFERROR(VLOOKUP(I45,Sheet1!$D$2:$F$52,3,TRUE),"")
A47: =IFERROR(VLOOKUP(A45,Sheet1!$D$2:$F$52,2,TRUE),"") | F47: =IFERROR(VLOOKUP(F45,Sheet1!$D$2:$F$52,2,TRUE),"") | G47: =IFERROR(VLOOKUP(G45,Sheet1!$D$2:$F$52,2,TRUE),"") | H47: =IFERROR(VLOOKUP(H45,Sheet1!$D$2:$F$52,2,TRUE),"") | I47: =IFERROR(VLOOKUP(I45,Sheet1!$D$2:$F$52,2,TRUE),"")
A50: =IFERROR(IF(A51="","","X"),"") | F50: =IFERROR(IF(F51="","","X"),"")
A51: =IFERROR(IF(AB2>2,AA4,""),"") | F51: =IFERROR(IF(AB2>3,AA5,""),"")
A52: =IFERROR(VLOOKUP(A51,Sheet1!$D$2:$F$52,3,TRUE),"") | F52: =IFERROR(VLOOKUP(F51,Sheet1!$D$2:$F$52,3,TRUE),"")
A53: =IFERROR(VLOOKUP(A51,Sheet1!$D$2:$F$52,2,TRUE),"") | F53: =IFERROR(VLOOKUP(F51,Sheet1!$D$2:$F$52,2,TRUE),"")
A56: =IFERROR(IF(A57="","","X"),"") | F56: =IFERROR(IF(F57="","","X"),"")
A57: =IFERROR(IF(AB2>4,AA6,""),"") | F57: =IFERROR(IF(AB2>5,AA7,""),"")
A58: =IFERROR(VLOOKUP(A57,Sheet1!$D$2:$F$52,3,TRUE),"") | F58: =IFERROR(VLOOKUP(F57,Sheet1!$D$2:$F$52,3,TRUE),"")
A59: =IFERROR(VLOOKUP(A57,Sheet1!$D$2:$F$52,2,TRUE),"") | F59: =IFERROR(VLOOKUP(F57,Sheet1!$D$2:$F$52,2,TRUE),"")

Sheet Jun
F1: Integrity Specialists, LLC 1151 Business Blvd Annandale, MN 55302 PH 503-437-3273
AA2: {=IFERROR(_xlfn.UNIQUE(_xlfn._xlws.FILTER(J7:J36,J7:J36<>"")),"")} | AB2: =COUNTA(AA:AA) -> 1
A3: Time in Method Summary
A4: Name: | B4: =IF(Jan!B4="","",Jan!B4) -> Your Name | C4: June | F4: =Jan!F4 -> 2024
E5: HOURS | J5: Supervising Technician
A6: Date | B6: Location | C6: MT | D6: PT | E6: ET | F6: UT | G6: VT | H6: LM | I6: PAUT
A7: {=IFERROR( _xlfn.LET( _xlpm.yr,$F$4, _xlpm.mn,IF(ISNUMBER($C$4),$C$4,MONTH(1&$C$4)), _xlpm.first,DATE(_xlpm.yr,_xlpm.mn,1), _xlpm.daysInMonth,DAY(EOMONTH(_xlpm.first,0)), TEXT(_xlpm.first+_xlfn.SEQUENCE(_xlpm.daysInMonth)-1,"dddd, mmmm d, yyyy") ), "")} -> Saturday, June 1, 2024
A8: Sunday, June 2, 2024
A9: Monday, June 3, 2024
A10: Tuesday, June 4, 2024
A11: Wednesday, June 5, 2024
A12: Thursday, June 6, 2024
A13: Friday, June 7, 2024
A14: Saturday, June 8, 2024
A15: Sunday, June 9, 2024
A16: Monday, June 10, 2024
A17: Tuesday, June 11, 2024
A18: Wednesday, June 12, 2024
A19: Thursday, June 13, 2024
... A36: Sunday, June 30, 2024
B39: =C4&" "&F4&" HOURS" -> June 2024 HOURS | C39: =SUM(C7:C38) -> 0 | D39: =SUM(D7:D38) -> 0 | E39: =SUM(E7:E38) -> 0 | F39: =SUM(F7:F38) -> 0 | G39: =SUM(G7:G38) -> 0 | H39: =SUM(H7:H38) -> 0 | I39: =SUM(I7:I38) -> 0
A43: =IFERROR(IF(A44="","","X"),"") | F43: =IFERROR(IF(F44="","","X"),"") | G43: =IFERROR(IF(G44="","","X"),"") | H43: =IFERROR(IF(H44="","","X"),"") | I43: =IFERROR(IF(I44="","","X"),"")
A44: =IFERROR(IF(AB2>0,AA2,""),"") | F44: =IFERROR(IF(AB$2>1,AA3,""),"")
A45: =IFERROR(VLOOKUP(A44,Sheet1!$D$2:$F$52,3,TRUE),"") | F45: =IFERROR(VLOOKUP(F44,Sheet1!$D$2:$F$52,3,TRUE),"") | G45: =IFERROR(VLOOKUP(G44,Sheet1!$D$2:$F$52,3,TRUE),"") | H45: =IFERROR(VLOOKUP(H44,Sheet1!$D$2:$F$52,3,TRUE),"") | I45: =IFERROR(VLOOKUP(I44,Sheet1!$D$2:$F$52,3,TRUE),"")
A46: =IFERROR(VLOOKUP(A44,Sheet1!$D$2:$F$52,2,TRUE),"") | F46: =IFERROR(VLOOKUP(F44,Sheet1!$D$2:$F$52,2,TRUE),"") | G46: =IFERROR(VLOOKUP(G44,Sheet1!$D$2:$F$52,2,TRUE),"") | H46: =IFERROR(VLOOKUP(H44,Sheet1!$D$2:$F$52,2,TRUE),"") | I46: =IFERROR(VLOOKUP(I44,Sheet1!$D$2:$F$52,2,TRUE),"")
A49: =IFERROR(IF(A50="","","X"),"") | F49: =IFERROR(IF(F50="","","X"),"")
A50: =IFERROR(IF(AB2>2,AA4,""),"") | F50: =IFERROR(IF(AB2>3,AA5,""),"")
A51: =IFERROR(VLOOKUP(A50,Sheet1!$D$2:$F$52,3,TRUE),"") | F51: =IFERROR(VLOOKUP(F50,Sheet1!$D$2:$F$52,3,TRUE),"")
A52: =IFERROR(VLOOKUP(A50,Sheet1!$D$2:$F$52,2,TRUE),"") | F52: =IFERROR(VLOOKUP(F50,Sheet1!$D$2:$F$52,2,TRUE),"")
A55: =IFERROR(IF(A56="","","X"),"") | F55: =IFERROR(IF(F56="","","X"),"")
A56: =IFERROR(IF(AB2>4,AA6,""),"") | F56: =IFERROR(IF(AB2>5,AA7,""),"")
A57: =IFERROR(VLOOKUP(A56,Sheet1!$D$2:$F$52,3,TRUE),"") | F57: =IFERROR(VLOOKUP(F56,Sheet1!$D$2:$F$52,3,TRUE),"")
A58: =IFERROR(VLOOKUP(A56,Sheet1!$D$2:$F$52,2,TRUE),"") | F58: =IFERROR(VLOOKUP(F56,Sheet1!$D$2:$F$52,2,TRUE),"")

Sheet Jul
F1: Integrity Specialists, LLC 1151 Business Blvd Annandale, MN 55302 PH 503-437-3273
AA2: {=IFERROR(_xlfn.UNIQUE(_xlfn._xlws.FILTER(J7:J37,J7:J37<>"")),"")} | AB2: =COUNTA(AA:AA) -> 1
A3: Time in Method Summary
A4: Name: | B4: =IF(Jan!B4="","",Jan!B4) -> Your Name | C4: July | F4: =Jan!F4 -> 2024
E5: HOURS | J5: Supervising Technician
A6: Date | B6: Location | C6: MT | D6: PT | E6: ET | F6: UT | G6: VT | H6: LM | I6: PAUT
A7: {=IFERROR( _xlfn.LET( _xlpm.yr,$F$4, _xlpm.mn,IF(ISNUMBER($C$4),$C$4,MONTH(1&$C$4)), _xlpm.first,DATE(_xlpm.yr,_xlpm.mn,1), _xlpm.daysInMonth,DAY(EOMONTH(_xlpm.first,0)), TEXT(_xlpm.first+_xlfn.SEQUENCE(_xlpm.daysInMonth)-1,"dddd, mmmm d, yyyy") ), "")} -> Monday, July 1, 2024
A8: Tuesday, July 2, 2024
A9: Wednesday, July 3, 2024
A10: Thursday, July 4, 2024
A11: Friday, July 5, 2024
A12: Saturday, July 6, 2024
A13: Sunday, July 7, 2024
A14: Monday, July 8, 2024
A15: Tuesday, July 9, 2024
A16: Wednesday, July 10, 2024
A17: Thursday, July 11, 2024
A18: Friday, July 12, 2024
A19: Saturday, July 13, 2024
... A37: Wednesday, July 31, 2024
B40: =C4&" "&F4&" HOURS" -> July 2024 HOURS | C40: =SUM(C7:C39) -> 0 | D40: =SUM(D7:D39) -> 0 | E40: =SUM(E7:E39) -> 0 | F40: =SUM(F7:F39) -> 0 | G40: =SUM(G7:G39) -> 0 | H40: =SUM(H7:H39) -> 0 | I40: =SUM(I7:I39) -> 0
A44: =IFERROR(IF(A45="","","X"),"") | F44: =IFERROR(IF(F45="","","X"),"") | G44: =IFERROR(IF(G45="","","X"),"") | H44: =IFERROR(IF(H45="","","X"),"") | I44: =IFERROR(IF(I45="","","X"),"")
A45: =IFERROR(IF(AB2>0,AA2,""),"") | F45: =IFERROR(IF(AB$2>1,AA3,""),"")
A46: =IFERROR(VLOOKUP(A45,Sheet1!$D$2:$F$52,3,TRUE),"") | F46: =IFERROR(VLOOKUP(F45,Sheet1!$D$2:$F$52,3,TRUE),"") | G46: =IFERROR(VLOOKUP(G45,Sheet1!$D$2:$F$52,3,TRUE),"") | H46: =IFERROR(VLOOKUP(H45,Sheet1!$D$2:$F$52,3,TRUE),"") | I46: =IFERROR(VLOOKUP(I45,Sheet1!$D$2:$F$52,3,TRUE),"")
A47: =IFERROR(VLOOKUP(A45,Sheet1!$D$2:$F$52,2,TRUE),"") | F47: =IFERROR(VLOOKUP(F45,Sheet1!$D$2:$F$52,2,TRUE),"") | G47: =IFERROR(VLOOKUP(G45,Sheet1!$D$2:$F$52,2,TRUE),"") | H47: =IFERROR(VLOOKUP(H45,Sheet1!$D$2:$F$52,2,TRUE),"") | I47: =IFERROR(VLOOKUP(I45,Sheet1!$D$2:$F$52,2,TRUE),"")
A50: =IFERROR(IF(A51="","","X"),"") | F50: =IFERROR(IF(F51="","","X"),"")
A51: =IFERROR(IF(AB2>2,AA4,""),"") | F51: =IFERROR(IF(AB2>3,AA5,""),"")
A52: =IFERROR(VLOOKUP(A51,Sheet1!$D$2:$F$52,3,TRUE),"") | F52: =IFERROR(VLOOKUP(F51,Sheet1!$D$2:$F$52,3,TRUE),"")
A53: =IFERROR(VLOOKUP(A51,Sheet1!$D$2:$F$52,2,TRUE),"") | F53: =IFERROR(VLOOKUP(F51,Sheet1!$D$2:$F$52,2,TRUE),"")
A56: =IFERROR(IF(A57="","","X"),"") | F56: =IFERROR(IF(F57="","","X"),"")
A57: =IFERROR(IF(AB2>4,AA6,""),"") | F57: =IFERROR(IF(AB2>5,AA7,""),"")
A58: =IFERROR(VLOOKUP(A57,Sheet1!$D$2:$F$52,3,TRUE),"") | F58: =IFERROR(VLOOKUP(F57,Sheet1!$D$2:$F$52,3,TRUE),"")
A59: =IFERROR(VLOOKUP(A57,Sheet1!$D$2:$F$52,2,TRUE),"") | F59: =IFERROR(VLOOKUP(F57,Sheet1!$D$2:$F$52,2,TRUE),"")

Sheet Aug
F1: Integrity Specialists, LLC 1151 Business Blvd Annandale, MN 55302 PH 503-437-3273
AA2: {=IFERROR(_xlfn.UNIQUE(_xlfn._xlws.FILTER(J7:J37,J7:J37<>"")),"")} | AB2: =COUNTA(AA:AA) -> 1
A3: Time in Method Summary
A4: Name: | B4: =IF(Jan!B4="","",Jan!B4) -> Your Name | C4: August | F4: =Jan!F4 -> 2024
E5: HOURS | J5: Supervising Technician
A6: Date | B6: Location | C6: MT | D6: PT | E6: ET | F6: UT | G6: VT | H6: LM | I6: PAUT
A7: {=IFERROR( _xlfn.LET( _xlpm.yr,$F$4, _xlpm.mn,IF(ISNUMBER($C$4),$C$4,MONTH(1&$C$4)), _xlpm.first,DATE(_xlpm.yr,_xlpm.mn,1), _xlpm.daysInMonth,DAY(EOMONTH(_xlpm.first,0)), TEXT(_xlpm.first+_xlfn.SEQUENCE(_xlpm.daysInMonth)-1,"dddd, mmmm d, yyyy") ), "")} -> Thursday, August 1, 2024
A8: Friday, August 2, 2024
A9: Saturday, August 3, 2024
A10: Sunday, August 4, 2024
A11: Monday, August 5, 2024
A12: Tuesday, August 6, 2024
A13: Wednesday, August 7, 2024
A14: Thursday, August 8, 2024
A15: Friday, August 9, 2024
A16: Saturday, August 10, 2024
A17: Sunday, August 11, 2024
A18: Monday, August 12, 2024
A19: Tuesday, August 13, 2024
... A37: Saturday, August 31, 2024
B40: =C4&" "&F4&" HOURS" -> August 2024 HOURS | C40: =SUM(C7:C39) -> 0 | D40: =SUM(D7:D39) -> 0 | E40: =SUM(E7:E39) -> 0 | F40: =SUM(F7:F39) -> 0 | G40: =SUM(G7:G39) -> 0 | H40: =SUM(H7:H39) -> 0 | I40: =SUM(I7:I39) -> 0
A44: =IFERROR(IF(A45="","","X"),"") | F44: =IFERROR(IF(F45="","","X"),"") | G44: =IFERROR(IF(G45="","","X"),"") | H44: =IFERROR(IF(H45="","","X"),"") | I44: =IFERROR(IF(I45="","","X"),"")
A45: =IFERROR(IF(AB2>0,AA2,""),"") | F45: =IFERROR(IF(AB$2>1,AA3,""),"")
A46: =IFERROR(VLOOKUP(A45,Sheet1!$D$2:$F$52,3,TRUE),"") | F46: =IFERROR(VLOOKUP(F45,Sheet1!$D$2:$F$52,3,TRUE),"") | G46: =IFERROR(VLOOKUP(G45,Sheet1!$D$2:$F$52,3,TRUE),"") | H46: =IFERROR(VLOOKUP(H45,Sheet1!$D$2:$F$52,3,TRUE),"") | I46: =IFERROR(VLOOKUP(I45,Sheet1!$D$2:$F$52,3,TRUE),"")
A47: =IFERROR(VLOOKUP(A45,Sheet1!$D$2:$F$52,2,TRUE),"") | F47: =IFERROR(VLOOKUP(F45,Sheet1!$D$2:$F$52,2,TRUE),"") | G47: =IFERROR(VLOOKUP(G45,Sheet1!$D$2:$F$52,2,TRUE),"") | H47: =IFERROR(VLOOKUP(H45,Sheet1!$D$2:$F$52,2,TRUE),"") | I47: =IFERROR(VLOOKUP(I45,Sheet1!$D$2:$F$52,2,TRUE),"")
A50: =IFERROR(IF(A51="","","X"),"") | F50: =IFERROR(IF(F51="","","X"),"")
A51: =IFERROR(IF(AB2>2,AA4,""),"") | F51: =IFERROR(IF(AB2>3,AA5,""),"")
A52: =IFERROR(VLOOKUP(A51,Sheet1!$D$2:$F$52,3,TRUE),"") | F52: =IFERROR(VLOOKUP(F51,Sheet1!$D$2:$F$52,3,TRUE),"")
A53: =IFERROR(VLOOKUP(A51,Sheet1!$D$2:$F$52,2,TRUE),"") | F53: =IFERROR(VLOOKUP(F51,Sheet1!$D$2:$F$52,2,TRUE),"")
A56: =IFERROR(IF(A57="","","X"),"") | F56: =IFERROR(IF(F57="","","X"),"")
A57: =IFERROR(IF(AB2>4,AA6,""),"") | F57: =IFERROR(IF(AB2>5,AA7,""),"")
A58: =IFERROR(VLOOKUP(A57,Sheet1!$D$2:$F$52,3,TRUE),"") | F58: =IFERROR(VLOOKUP(F57,Sheet1!$D$2:$F$52,3,TRUE),"")
A59: =IFERROR(VLOOKUP(A57,Sheet1!$D$2:$F$52,2,TRUE),"") | F59: =IFERROR(VLOOKUP(F57,Sheet1!$D$2:$F$52,2,TRUE),"")

Sheet Sep
F1: Integrity Specialists, LLC 1151 Business Blvd Annandale, MN 55302 PH 503-437-3273
AA2: {=IFERROR(_xlfn.UNIQUE(_xlfn._xlws.FILTER(J7:J36,J7:J36<>"")),"")} | AB2: =COUNTA(AA:AA) -> 1
A3: Time in Method Summary
A4: Name: | B4: =IF(Jan!B4="","",Jan!B4) -> Your Name | C4: September | F4: =Jan!F4 -> 2024
E5: HOURS | J5: Supervising Technician
A6: Date | B6: Location | C6: MT | D6: PT | E6: ET | F6: UT | G6: VT | H6: LM | I6: PAUT
A7: {=IFERROR( _xlfn.LET( _xlpm.yr,$F$4, _xlpm.mn,IF(ISNUMBER($C$4),$C$4,MONTH(1&$C$4)), _xlpm.first,DATE(_xlpm.yr,_xlpm.mn,1), _xlpm.daysInMonth,DAY(EOMONTH(_xlpm.first,0)), TEXT(_xlpm.first+_xlfn.SEQUENCE(_xlpm.daysInMonth)-1,"dddd, mmmm d, yyyy") ), "")} -> Sunday, September 1, 2024
A8: Monday, September 2, 2024
A9: Tuesday, September 3, 2024
A10: Wednesday, September 4, 2024
A11: Thursday, September 5, 2024
A12: Friday, September 6, 2024
A13: Saturday, September 7, 2024
A14: Sunday, September 8, 2024
A15: Monday, September 9, 2024
A16: Tuesday, September 10, 2024
A17: Wednesday, September 11, 2024
A18: Thursday, September 12, 2024
A19: Friday, September 13, 2024
... A36: Monday, September 30, 2024
B39: =C4&" "&F4&" HOURS" -> September 2024 HOURS | C39: =SUM(C7:C38) -> 0 | D39: =SUM(D7:D38) -> 0 | E39: =SUM(E7:E38) -> 0 | F39: =SUM(F7:F38) -> 0 | G39: =SUM(G7:G38) -> 0 | H39: =SUM(H7:H38) -> 0 | I39: =SUM(I7:I38) -> 0
A43: =IFERROR(IF(A44="","","X"),"") | F43: =IFERROR(IF(F44="","","X"),"") | G43: =IFERROR(IF(G44="","","X"),"") | H43: =IFERROR(IF(H44="","","X"),"") | I43: =IFERROR(IF(I44="","","X"),"")
A44: =IFERROR(IF(AB2>0,AA2,""),"") | F44: =IFERROR(IF(AB$2>1,AA3,""),"")
A45: =IFERROR(VLOOKUP(A44,Sheet1!$D$2:$F$52,3,TRUE),"") | F45: =IFERROR(VLOOKUP(F44,Sheet1!$D$2:$F$52,3,TRUE),"") | G45: =IFERROR(VLOOKUP(G44,Sheet1!$D$2:$F$52,3,TRUE),"") | H45: =IFERROR(VLOOKUP(H44,Sheet1!$D$2:$F$52,3,TRUE),"") | I45: =IFERROR(VLOOKUP(I44,Sheet1!$D$2:$F$52,3,TRUE),"")
A46: =IFERROR(VLOOKUP(A44,Sheet1!$D$2:$F$52,2,TRUE),"") | F46: =IFERROR(VLOOKUP(F44,Sheet1!$D$2:$F$52,2,TRUE),"") | G46: =IFERROR(VLOOKUP(G44,Sheet1!$D$2:$F$52,2,TRUE),"") | H46: =IFERROR(VLOOKUP(H44,Sheet1!$D$2:$F$52,2,TRUE),"") | I46: =IFERROR(VLOOKUP(I44,Sheet1!$D$2:$F$52,2,TRUE),"")
A49: =IFERROR(IF(A50="","","X"),"") | F49: =IFERROR(IF(F50="","","X"),"")
A50: =IFERROR(IF(AB2>2,AA4,""),"") | F50: =IFERROR(IF(AB2>3,AA5,""),"")
A51: =IFERROR(VLOOKUP(A50,Sheet1!$D$2:$F$52,3,TRUE),"") | F51: =IFERROR(VLOOKUP(F50,Sheet1!$D$2:$F$52,3,TRUE),"")
A52: =IFERROR(VLOOKUP(A50,Sheet1!$D$2:$F$52,2,TRUE),"") | F52: =IFERROR(VLOOKUP(F50,Sheet1!$D$2:$F$52,2,TRUE),"")
A55: =IFERROR(IF(A56="","","X"),"") | F55: =IFERROR(IF(F56="","","X"),"")
A56: =IFERROR(IF(AB2>4,AA6,""),"") | F56: =IFERROR(IF(AB2>5,AA7,""),"")
A57: =IFERROR(VLOOKUP(A56,Sheet1!$D$2:$F$52,3,TRUE),"") | F57: =IFERROR(VLOOKUP(F56,Sheet1!$D$2:$F$52,3,TRUE),"")
A58: =IFERROR(VLOOKUP(A56,Sheet1!$D$2:$F$52,2,TRUE),"") | F58: =IFERROR(VLOOKUP(F56,Sheet1!$D$2:$F$52,2,TRUE),"")

Sheet Oct
F1: Integrity Specialists, LLC 1151 Business Blvd Annandale, MN 55302 PH 503-437-3273
AA2: {=IFERROR(_xlfn.UNIQUE(_xlfn._xlws.FILTER(J7:J37,J7:J37<>"")),"")} | AB2: =COUNTA(AA:AA) -> 1
A3: Time in Method Summary
A4: Name: | B4: =IF(Jan!B4="","",Jan!B4) -> Your Name | C4: October | F4: =Jan!F4 -> 2024
E5: HOURS | J5: Supervising Technician
A6: Date | B6: Location | C6: MT | D6: PT | E6: ET | F6: UT | G6: VT | H6: LM | I6: PAUT
A7: {=IFERROR( _xlfn.LET( _xlpm.yr,$F$4, _xlpm.mn,IF(ISNUMBER($C$4),$C$4,MONTH(1&$C$4)), _xlpm.first,DATE(_xlpm.yr,_xlpm.mn,1), _xlpm.daysInMonth,DAY(EOMONTH(_xlpm.first,0)), TEXT(_xlpm.first+_xlfn.SEQUENCE(_xlpm.daysInMonth)-1,"dddd, mmmm d, yyyy") ), "")} -> Tuesday, October 1, 2024
A8: Wednesday, October 2, 2024
A9: Thursday, October 3, 2024
A10: Friday, October 4, 2024
A11: Saturday, October 5, 2024
A12: Sunday, October 6, 2024
A13: Monday, October 7, 2024
A14: Tuesday, October 8, 2024
A15: Wednesday, October 9, 2024
A16: Thursday, October 10, 2024
A17: Friday, October 11, 2024
A18: Saturday, October 12, 2024
A19: Sunday, October 13, 2024
... A37: Thursday, October 31, 2024
B40: =C4&" "&F4&" HOURS" -> October 2024 HOURS | C40: =SUM(C7:C39) -> 0 | D40: =SUM(D7:D39) -> 0 | E40: =SUM(E7:E39) -> 0 | F40: =SUM(F7:F39) -> 0 | G40: =SUM(G7:G39) -> 0 | H40: =SUM(H7:H39) -> 0 | I40: =SUM(I7:I39) -> 0
A44: =IFERROR(IF(A45="","","X"),"") | F44: =IFERROR(IF(F45="","","X"),"") | G44: =IFERROR(IF(G45="","","X"),"") | H44: =IFERROR(IF(H45="","","X"),"") | I44: =IFERROR(IF(I45="","","X"),"")
A45: =IFERROR(IF(AB2>0,AA2,""),"") | F45: =IFERROR(IF(AB$2>1,AA3,""),"")
A46: =IFERROR(VLOOKUP(A45,Sheet1!$D$2:$F$52,3,TRUE),"") | F46: =IFERROR(VLOOKUP(F45,Sheet1!$D$2:$F$52,3,TRUE),"") | G46: =IFERROR(VLOOKUP(G45,Sheet1!$D$2:$F$52,3,TRUE),"") | H46: =IFERROR(VLOOKUP(H45,Sheet1!$D$2:$F$52,3,TRUE),"") | I46: =IFERROR(VLOOKUP(I45,Sheet1!$D$2:$F$52,3,TRUE),"")
A47: =IFERROR(VLOOKUP(A45,Sheet1!$D$2:$F$52,2,TRUE),"") | F47: =IFERROR(VLOOKUP(F45,Sheet1!$D$2:$F$52,2,TRUE),"") | G47: =IFERROR(VLOOKUP(G45,Sheet1!$D$2:$F$52,2,TRUE),"") | H47: =IFERROR(VLOOKUP(H45,Sheet1!$D$2:$F$52,2,TRUE),"") | I47: =IFERROR(VLOOKUP(I45,Sheet1!$D$2:$F$52,2,TRUE),"")
A50: =IFERROR(IF(A51="","","X"),"") | F50: =IFERROR(IF(F51="","","X"),"")
A51: =IFERROR(IF(AB2>2,AA4,""),"") | F51: =IFERROR(IF(AB2>3,AA5,""),"")
A52: =IFERROR(VLOOKUP(A51,Sheet1!$D$2:$F$52,3,TRUE),"") | F52: =IFERROR(VLOOKUP(F51,Sheet1!$D$2:$F$52,3,TRUE),"")
A53: =IFERROR(VLOOKUP(A51,Sheet1!$D$2:$F$52,2,TRUE),"") | F53: =IFERROR(VLOOKUP(F51,Sheet1!$D$2:$F$52,2,TRUE),"")
A56: =IFERROR(IF(A57="","","X"),"") | F56: =IFERROR(IF(F57="","","X"),"")
A57: =IFERROR(IF(AB2>4,AA6,""),"") | F57: =IFERROR(IF(AB2>5,AA7,""),"")
A58: =IFERROR(VLOOKUP(A57,Sheet1!$D$2:$F$52,3,TRUE),"") | F58: =IFERROR(VLOOKUP(F57,Sheet1!$D$2:$F$52,3,TRUE),"")
A59: =IFERROR(VLOOKUP(A57,Sheet1!$D$2:$F$52,2,TRUE),"") | F59: =IFERROR(VLOOKUP(F57,Sheet1!$D$2:$F$52,2,TRUE),"")

Sheet Nov
F1: Integrity Specialists, LLC 1151 Business Blvd Annandale, MN 55302 PH 503-437-3273
AA2: {=IFERROR(_xlfn.UNIQUE(_xlfn._xlws.FILTER(J7:J36,J7:J36<>"")),"")} | AB2: =COUNTA(AA:AA) -> 1
A3: Time in Method Summary
A4: Name: | B4: =IF(Jan!B4="","",Jan!B4) -> Your Name | C4: November | F4: =Jan!F4 -> 2024
E5: HOURS | J5: Supervising Technician
A6: Date | B6: Location | C6: MT | D6: PT | E6: ET | F6: UT | G6: VT | H6: LM | I6: PAUT
A7: {=IFERROR( _xlfn.LET( _xlpm.yr,$F$4, _xlpm.mn,IF(ISNUMBER($C$4),$C$4,MONTH(1&$C$4)), _xlpm.first,DATE(_xlpm.yr,_xlpm.mn,1), _xlpm.daysInMonth,DAY(EOMONTH(_xlpm.first,0)), TEXT(_xlpm.first+_xlfn.SEQUENCE(_xlpm.daysInMonth)-1,"dddd, mmmm d, yyyy") ), "")} -> Friday, November 1, 2024
A8: Saturday, November 2, 2024
A9: Sunday, November 3, 2024
A10: Monday, November 4, 2024
A11: Tuesday, November 5, 2024
A12: Wednesday, November 6, 2024
A13: Thursday, November 7, 2024
A14: Friday, November 8, 2024
A15: Saturday, November 9, 2024
A16: Sunday, November 10, 2024
A17: Monday, November 11, 2024
A18: Tuesday, November 12, 2024
A19: Wednesday, November 13, 2024
... A36: Saturday, November 30, 2024
B39: =C4&" "&F4&" HOURS" -> November 2024 HOURS | C39: =SUM(C7:C38) -> 0 | D39: =SUM(D7:D38) -> 0 | E39: =SUM(E7:E38) -> 0 | F39: =SUM(F7:F38) -> 0 | G39: =SUM(G7:G38) -> 0 | H39: =SUM(H7:H38) -> 0 | I39: =SUM(I7:I38) -> 0
A43: =IFERROR(IF(A44="","","X"),"") | F43: =IFERROR(IF(F44="","","X"),"") | G43: =IFERROR(IF(G44="","","X"),"") | H43: =IFERROR(IF(H44="","","X"),"") | I43: =IFERROR(IF(I44="","","X"),"")
A44: =IFERROR(IF(AB2>0,AA2,""),"") | F44: =IFERROR(IF(AB$2>1,AA3,""),"")
A45: =IFERROR(VLOOKUP(A44,Sheet1!$D$2:$F$52,3,TRUE),"") | F45: =IFERROR(VLOOKUP(F44,Sheet1!$D$2:$F$52,3,TRUE),"") | G45: =IFERROR(VLOOKUP(G44,Sheet1!$D$2:$F$52,3,TRUE),"") | H45: =IFERROR(VLOOKUP(H44,Sheet1!$D$2:$F$52,3,TRUE),"") | I45: =IFERROR(VLOOKUP(I44,Sheet1!$D$2:$F$52,3,TRUE),"")
A46: =IFERROR(VLOOKUP(A44,Sheet1!$D$2:$F$52,2,TRUE),"") | F46: =IFERROR(VLOOKUP(F44,Sheet1!$D$2:$F$52,2,TRUE),"") | G46: =IFERROR(VLOOKUP(G44,Sheet1!$D$2:$F$52,2,TRUE),"") | H46: =IFERROR(VLOOKUP(H44,Sheet1!$D$2:$F$52,2,TRUE),"") | I46: =IFERROR(VLOOKUP(I44,Sheet1!$D$2:$F$52,2,TRUE),"")
A49: =IFERROR(IF(A50="","","X"),"") | F49: =IFERROR(IF(F50="","","X"),"")
A50: =IFERROR(IF(AB2>2,AA4,""),"") | F50: =IFERROR(IF(AB2>3,AA5,""),"")
A51: =IFERROR(VLOOKUP(A50,Sheet1!$D$2:$F$52,3,TRUE),"") | F51: =IFERROR(VLOOKUP(F50,Sheet1!$D$2:$F$52,3,TRUE),"")
A52: =IFERROR(VLOOKUP(A50,Sheet1!$D$2:$F$52,2,TRUE),"") | F52: =IFERROR(VLOOKUP(F50,Sheet1!$D$2:$F$52,2,TRUE),"")
A55: =IFERROR(IF(A56="","","X"),"") | F55: =IFERROR(IF(F56="","","X"),"")
A56: =IFERROR(IF(AB2>4,AA6,""),"") | F56: =IFERROR(IF(AB2>5,AA7,""),"")
A57: =IFERROR(VLOOKUP(A56,Sheet1!$D$2:$F$52,3,TRUE),"") | F57: =IFERROR(VLOOKUP(F56,Sheet1!$D$2:$F$52,3,TRUE),"")
A58: =IFERROR(VLOOKUP(A56,Sheet1!$D$2:$F$52,2,TRUE),"") | F58: =IFERROR(VLOOKUP(F56,Sheet1!$D$2:$F$52,2,TRUE),"")

Sheet Dec
F1: Integrity Specialists, LLC 1151 Business Blvd Annandale, MN 55302 PH 503-437-3273
AA2: {=IFERROR(_xlfn.UNIQUE(_xlfn._xlws.FILTER(J7:J37,J7:J37<>"")),"")} | AB2: =COUNTA(AA:AA) -> 1
A3: Time in Method Summary
A4: Name: | B4: =IF(Jan!B4="","",Jan!B4) -> Your Name | C4: December | F4: =Jan!F4 -> 2024
E5: HOURS | J5: Supervising Technician
A6: Date | B6: Location | C6: MT | D6: PT | E6: ET | F6: UT | G6: VT | H6: LM | I6: PAUT
A7: {=IFERROR( _xlfn.LET( _xlpm.yr,$F$4, _xlpm.mn,IF(ISNUMBER($C$4),$C$4,MONTH(1&$C$4)), _xlpm.first,DATE(_xlpm.yr,_xlpm.mn,1), _xlpm.daysInMonth,DAY(EOMONTH(_xlpm.first,0)), TEXT(_xlpm.first+_xlfn.SEQUENCE(_xlpm.daysInMonth)-1,"dddd, mmmm d, yyyy") ), "")} -> Sunday, December 1, 2024
A8: Monday, December 2, 2024
A9: Tuesday, December 3, 2024
A10: Wednesday, December 4, 2024
A11: Thursday, December 5, 2024
A12: Friday, December 6, 2024
A13: Saturday, December 7, 2024
A14: Sunday, December 8, 2024
A15: Monday, December 9, 2024
A16: Tuesday, December 10, 2024
A17: Wednesday, December 11, 2024
A18: Thursday, December 12, 2024
A19: Friday, December 13, 2024
... A37: Tuesday, December 31, 2024
B40: =C4&" "&F4&" HOURS" -> December 2024 HOURS | C40: =SUM(C7:C39) -> 0 | D40: =SUM(D7:D39) -> 0 | E40: =SUM(E7:E39) -> 0 | F40: =SUM(F7:F39) -> 0 | G40: =SUM(G7:G39) -> 0 | H40: =SUM(H7:H39) -> 0 | I40: =SUM(I7:I39) -> 0
A44: =IFERROR(IF(A45="","","X"),"") | F44: =IFERROR(IF(F45="","","X"),"") | G44: =IFERROR(IF(G45="","","X"),"") | H44: =IFERROR(IF(H45="","","X"),"") | I44: =IFERROR(IF(I45="","","X"),"")
A45: =IFERROR(IF(AB2>0,AA2,""),"") | F45: =IFERROR(IF(AB$2>1,AA3,""),"")
A46: =IFERROR(VLOOKUP(A45,Sheet1!$D$2:$F$52,3,TRUE),"") | F46: =IFERROR(VLOOKUP(F45,Sheet1!$D$2:$F$52,3,TRUE),"") | G46: =IFERROR(VLOOKUP(G45,Sheet1!$D$2:$F$52,3,TRUE),"") | H46: =IFERROR(VLOOKUP(H45,Sheet1!$D$2:$F$52,3,TRUE),"") | I46: =IFERROR(VLOOKUP(I45,Sheet1!$D$2:$F$52,3,TRUE),"")
A47: =IFERROR(VLOOKUP(A45,Sheet1!$D$2:$F$52,2,TRUE),"") | F47: =IFERROR(VLOOKUP(F45,Sheet1!$D$2:$F$52,2,TRUE),"") | G47: =IFERROR(VLOOKUP(G45,Sheet1!$D$2:$F$52,2,TRUE),"") | H47: =IFERROR(VLOOKUP(H45,Sheet1!$D$2:$F$52,2,TRUE),"") | I47: =IFERROR(VLOOKUP(I45,Sheet1!$D$2:$F$52,2,TRUE),"")
A50: =IFERROR(IF(A51="","","X"),"") | F50: =IFERROR(IF(F51="","","X"),"")
A51: =IFERROR(IF(AB2>2,AA4,""),"") | F51: =IFERROR(IF(AB2>3,AA5,""),"")
A52: =IFERROR(VLOOKUP(A51,Sheet1!$D$2:$F$52,3,TRUE),"") | F52: =IFERROR(VLOOKUP(F51,Sheet1!$D$2:$F$52,3,TRUE),"")
A53: =IFERROR(VLOOKUP(A51,Sheet1!$D$2:$F$52,2,TRUE),"") | F53: =IFERROR(VLOOKUP(F51,Sheet1!$D$2:$F$52,2,TRUE),"")
A56: =IFERROR(IF(A57="","","X"),"") | F56: =IFERROR(IF(F57="","","X"),"")
A57: =IFERROR(IF(AB2>4,AA6,""),"") | F57: =IFERROR(IF(AB2>5,AA7,""),"")
A58: =IFERROR(VLOOKUP(A57,Sheet1!$D$2:$F$52,3,TRUE),"") | F58: =IFERROR(VLOOKUP(F57,Sheet1!$D$2:$F$52,3,TRUE),"")
A59: =IFERROR(VLOOKUP(A57,Sheet1!$D$2:$F$52,2,TRUE),"") | F59: =IFERROR(VLOOKUP(F57,Sheet1!$D$2:$F$52,2,TRUE),"")

Sheet Annual Summary
F1: Integrity Specialists, LLC 1151 Business Blvd Annandale, MN 55302 PH 503-437-3273
C3: Time in Method | E3: =Jan!F4 -> 2024 | F3: Annual Summary
A4: Name: | B4: =IF(Jan!B4="","",Jan!B4) -> Your Name
E5: HOURS
A6: Date | B6: Locations | C6: MT | D6: PT | E6: ET | F6: UT | G6: VT | H6: LM | I6: PAUT
A7: January | C7: =Jan!C40 -> 0 | D7: =Jan!D40 -> 0 | E7: =Jan!E40 -> 0 | F7: =Jan!F40 -> 0 | G7: =Jan!G40 -> 0 | H7: =Jan!H40 -> 0 | I7: =Jan!I40 -> 0
A8: February | C8: =Feb!C38 -> 0 | D8: =Feb!D38 -> 0 | E8: =Feb!E38 -> 0 | F8: =Feb!F38 -> 0 | G8: =Feb!G38 -> 0 | H8: =Feb!H38 -> 0 | I8: =Feb!I38 -> 0
A9: March | C9: =Mar!C40 -> 0 | D9: =Mar!D40 -> 0 | E9: =Mar!E40 -> 0 | F9: =Mar!F40 -> 0 | G9: =Mar!G40 -> 0 | H9: =Mar!H40 -> 0 | I9: =Mar!I40 -> 0
A10: April | C10: =Apr!C39 -> 0 | D10: =Apr!D39 -> 0 | E10: =Apr!E39 -> 0 | F10: =Apr!F39 -> 0 | G10: =Apr!G39 -> 0 | H10: =Apr!H39 -> 0 | I10: =Apr!I39 -> 0
A11: May | C11: =May!C40 -> 0 | D11: =May!D40 -> 0 | E11: =May!E40 -> 0 | F11: =May!F40 -> 0 | G11: =May!G40 -> 0 | H11: =May!H40 -> 0 | I11: =May!I40 -> 0
A12: June | C12: =Jun!C39 -> 0 | D12: =Jun!D39 -> 0 | E12: =Jun!E39 -> 0 | F12: =Jun!F39 -> 0 | G12: =Jun!G39 -> 0 | H12: =Jun!H39 -> 0 | I12: =Jun!I39 -> 0
A13: July | C13: =Jul!C40 -> 0 | D13: =Jul!D40 -> 0 | E13: =Jul!E40 -> 0 | F13: =Jul!F40 -> 0 | G13: =Jul!G40 -> 0 | H13: =Jul!H40 -> 0 | I13: =Jul!I40 -> 0
A14: August | C14: =Aug!C40 -> 0 | D14: =Aug!D40 -> 0 | E14: =Aug!E40 -> 0 | F14: =Aug!F40 -> 0 | G14: =Aug!G40 -> 0 | H14: =Aug!H40 -> 0 | I14: =Aug!I40 -> 0
A15: September | C15: =Sep!C39 -> 0 | D15: =Sep!D39 -> 0 | E15: =Sep!E39 -> 0 | F15: =Sep!F39 -> 0 | G15: =Sep!G39 -> 0 | H15: =Sep!H39 -> 0 | I15: =Sep!I39 -> 0
A16: October | C16: =Oct!C40 -> 0 | D16: =Oct!D40 -> 0 | E16: =Oct!E40 -> 0 | F16: =Oct!F40 -> 0 | G16: =Oct!G40 -> 0 | H16: =Oct!H40 -> 0 | I16: =Oct!I40 -> 0
A17: November | C17: =Nov!C39 -> 0 | D17: =Nov!D39 -> 0 | E17: =Nov!E39 -> 0 | F17: =Nov!F39 -> 0 | G17: =Nov!G39 -> 0 | H17: =Nov!H39 -> 0 | I17: =Nov!I39 -> 0
A18: December | C18: =Dec!C40 -> 0 | D18: =Dec!D40 -> 0 | E18: =Dec!E40 -> 0 | F18: =Dec!F40 -> 0 | G18: =Dec!G40 -> 0 | H18: =Dec!H40 -> 0 | I18: =Dec!I40 -> 0
B20: =E3&" TOTAL HOURS" -> 2024 TOTAL HOURS | C20: =SUM(C7:C18) -> 0 | D20: =SUM(D7:D18) -> 0 | E20: =SUM(E7:E18) -> 0 | F20: =SUM(F7:F18) -> 0 | G20: =SUM(G7:G18) -> 0 | H20: =SUM(H7:H18) -> 0 | I20: =SUM(I7:I18) -> 0
A23: X
A24: Larry@integrityspecialists.com
A25: ASNT Level III # 48461
A26: larry@integrityspecialists.com
